Traceback (most recent call last):
  File "/root/Desktop/PCBA2/bin/pcba_ate.py", line 636, in operate
    self.lab_iperfeth.setText(str(getresq[1]))
AttributeError: 'mbox' object has no attribute 'lab_iperfeth'
Traceback (most recent call last):
  File "/root/Desktop/PCBA2/bin/pcba_ate.py", line 674, in operate
    self.edit_ethmac.text(str(getresq[2]))
TypeError: text(self): too many arguments
Traceback (most recent call last):
  File "/root/Desktop/PCBA2/bin/pcba_ate.py", line 328, in auto_clicked
    _thread.start_new_thread(auto,(ser,resq,res_value,ir_port,ser_switch,recordinput,target_freq,powerwifi_range,hostname,username,password,portnum,database,table,new_sn))
NameError: name 'ser' is not defined
Traceback (most recent call last):
  File "/root/Desktop/PCBA2/bin/pcba_ate.py", line 328, in auto_clicked
    _thread.start_new_thread(auto,(ser_linux,resq,res_value,ir_port,ser_switch,recordinput,target_freq,powerwifi_range,hostname,username,password,portnum,database,table,new_sn))
UnboundLocalError: local variable 'new_sn' referenced before assignment
Traceback (most recent call last):
  File "/root/Desktop/PCBA2/bin/pcba_ate.py", line 325, in auto_clicked
    _thread.start_new_thread(auto,(ser_linux,resq,res_value,ir_port,ser_switch,recordinput,target_freq,powerwifi_range,hostname,username,password,portnum,database,table,new_sn))
UnboundLocalError: local variable 'new_sn' referenced before assignment
Traceback (most recent call last):
  File "/root/Desktop/PCBA2/bin/pcba_ate.py", line 325, in auto_clicked
    _thread.start_new_thread(auto,(ser_linux,resq,res_value,ir_port,ser_switch,recordinput,target_freq,powerwifi_range,hostname,username,password,portnum,database,table,new_sn))
UnboundLocalError: local variable 'new_sn' referenced before assignment
Traceback (most recent call last):
  File "/root/Desktop/PCBA2/bin/pcba_func.py", line 1222, in auto
    vol(resq)
TypeError: vol() missing 3 required positional arguments: 'dc1_range', 'tp28_range', and 'resq'
Traceback (most recent call last):
  File "/root/Desktop/PCBA2/bin/pcba_ate.py", line 325, in auto_clicked
    _thread.start_new_thread(auto,(ser_linux,resq,res_value,dc1_range,tp28_range,ir_port,ser_switch,recordinput,target_freq,powerwifi_range,hostname,username,password,portnum,database,table,new_sn))
UnboundLocalError: local variable 'new_sn' referenced before assignment
Traceback (most recent call last):
  File "/root/Desktop/PCBA2/bin/pcba_func.py", line 1222, in auto
    vol(ser_switch,dc1_range,tp28_range)
TypeError: vol() missing 1 required positional argument: 'resq'
Traceback (most recent call last):
  File "/root/Desktop/PCBA2/bin/pcba_ate.py", line 325, in auto_clicked
    _thread.start_new_thread(auto,(ser_linux,resq,res_value,dc1_range,tp28_range,ser_ir,ser_switch,senvol_range,relayvol_range,recordinput,target_freq,powerwifi_range,hostname,username,password,portnum,database,table,new_sn))
NameError: name 'senvol_range' is not defined
Traceback (most recent call last):
  File "/root/Desktop/PCBA2/bin/pcba_func.py", line 1243, in auto
    IR_test(ser,ir_port,True,resq)
NameError: name 'IR_test' is not defined
Traceback (most recent call last):
  File "/root/Desktop/PCBA2/bin/pcba_ate.py", line 325, in auto_clicked
    _thread.start_new_thread(auto,(ser_linux,resq,res_value,dc1_range,tp28_range,ser_ir,ser_switch,sensevol_range,relayvol_range,recordinput,target_freq,powerwifi_range,hostname,username,password,portnum,database,table,new_sn))
UnboundLocalError: local variable 'new_sn' referenced before assignment
Traceback (most recent call last):
  File "/root/Desktop/PCBA2/bin/pcba_func.py", line 1243, in auto
    ir_test(ser,ir_port,True,resq)
TypeError: ir_test() takes 3 positional arguments but 4 were given
Traceback (most recent call last):
  File "/root/Desktop/PCBA2/bin/pcba_ate.py", line 325, in auto_clicked
    _thread.start_new_thread(auto,(ser_linux,resq,res_value,dc1_range,tp28_range,ser_ir,ser_switch,sensevol_range,relayvol_range,recordinput,target_freq,powerwifi_range,hostname,username,password,portnum,database,table,new_sn))
UnboundLocalError: local variable 'new_sn' referenced before assignment
Traceback (most recent call last):
  File "/root/Desktop/PCBA2/bin/pcba_func.py", line 1244, in auto
    ir_test(ser,ir_port,True,resq)
TypeError: ir_test() takes 3 positional arguments but 4 were given
Traceback (most recent call last):
  File "/root/Desktop/PCBA2/bin/pcba_func.py", line 1265, in auto
    sense_test(ser,ser_switch,sensevol_range,resq)
NameError: name 'sensevol_range' is not defined
Traceback (most recent call last):
  File "/root/Desktop/PCBA2/bin/pcba_ate.py", line 325, in auto_clicked
    _thread.start_new_thread(auto,(ser_linux,resq,res_value,dc1_range,tp28_range,ser_ir,ser_switch,sensevol_range,relayvol_range,recordinput,target_freq,powerwifi_range,hostname,username,password,portnum,database,table,new_sn))
UnboundLocalError: local variable 'new_sn' referenced before assignment
Traceback (most recent call last):
  File "/root/Desktop/PCBA2/bin/pcba_ate.py", line 325, in auto_clicked
    _thread.start_new_thread(auto,(ser_linux,resq,res_value,dc1_range,tp28_range,ser_ir,ser_switch,sensevol_range,relayvol_range,recordinput,target_freq,powerwifi_range,hostname,username,password,portnum,database,table,new_sn))
UnboundLocalError: local variable 'new_sn' referenced before assignment
Traceback (most recent call last):
  File "/root/Desktop/PCBA2/bin/pcba_func.py", line 1214, in auto
    inforw(ser,hostname,username,password,portnum,database,table,new_sn,resq)
NameError: name 'inforw' is not defined
Traceback (most recent call last):
  File "/root/Desktop/PCBA2/bin/pcba_func.py", line 1204, in auto
    fetch_power(ser,resq,target_freq,powerwifi_range)
  File "/root/Desktop/PCBA2/bin/pcba_func.py", line 453, in fetch_power
    hackrf.sample_rate = 20e6
NameError: name 'hackrf' is not defined
Traceback (most recent call last):
  File "/root/Desktop/PCBA2/bin/pcba_ate.py", line 326, in auto_clicked
    _thread.start_new_thread(auto,(ser_linux,resq,res_value,dc1_range,tp28_range,ser_ir,ser_switch,sensevol_range,relayvol_range,recordinput,target_freq,powerwifi_range,hostname,username,password,portnum,database,table,new_sn))
UnboundLocalError: local variable 'new_sn' referenced before assignment
Traceback (most recent call last):
  File "/root/Desktop/PCBA2/bin/pcba_ate.py", line 326, in auto_clicked
    _thread.start_new_thread(auto,(ser_linux,resq,res_value,dc1_range,tp28_range,ser_ir,ser_switch,sensevol_range,relayvol_range,recordinput,target_freq,powerwifi_range,hostname,username,password,portnum,database,table,new_sn))
UnboundLocalError: local variable 'new_sn' referenced before assignment
Traceback (most recent call last):
  File "/root/Desktop/PCBA2/bin/pcba_ate.py", line 326, in auto_clicked
    _thread.start_new_thread(auto,(ser_linux,resq,res_value,dc1_range,tp28_range,ser_ir,ser_switch,sensevol_range,relayvol_range,recordinput,target_freq,powerwifi_range,hostname,username,password,portnum,database,table,new_sn))
UnboundLocalError: local variable 'new_sn' referenced before assignment
Traceback (most recent call last):
  File "/root/Desktop/PCBA2/bin/pcba_ate.py", line 327, in auto_clicked
    _thread.start_new_thread(auto,(ser_linux,resq,res_value,dc1_range,tp28_range,ser_ir,ser_switch,sensevol_range,relayvol_range,recordinput,target_freq,powerwifi_range,hostname,username,password,portnum,database,table,new_sn))
UnboundLocalError: local variable 'new_sn' referenced before assignment
Traceback (most recent call last):
  File "/root/Desktop/PCBA2/bin/pcba_ate.py", line 326, in auto_clicked
    _thread.start_new_thread(auto,(ser_linux,resq,res_value,dc1_range,tp28_range,ser_ir,ser_switch,sensevol_range,relayvol_range,recordinput,target_freq,powerwifi_range,hostname,username,password,portnum,database,table,new_sn))
UnboundLocalError: local variable 'new_sn' referenced before assignment
Traceback (most recent call last):
  File "/root/Desktop/PCBA2/bin/pcba_ate.py", line 326, in auto_clicked
    _thread.start_new_thread(auto,(ser_linux,resq,res_value,dc1_range,tp28_range,ser_ir,ser_switch,sensevol_range,relayvol_range,recordinput,target_freq,powerwifi_range,hostname,username,password,portnum,database,table,new_sn))
UnboundLocalError: local variable 'new_sn' referenced before assignment
Traceback (most recent call last):
  File "/root/Desktop/PCBA2/bin/pcba_ate.py", line 326, in auto_clicked
    _thread.start_new_thread(auto,(ser_linux,resq,res_value,dc1_range,tp28_range,ser_ir,ser_switch,sensevol_range,relayvol_range,recordinput,target_freq,powerwifi_range,hostname,username,password,portnum,database,table,new_sn))
UnboundLocalError: local variable 'new_sn' referenced before assignment
Traceback (most recent call last):
  File "/root/Desktop/PCBA2/bin/pcba_ate.py", line 327, in auto_clicked
    _thread.start_new_thread(auto,(ser_linux,resq,res_value,dc1_range,tp28_range,ser_ir,ser_switch,sensevol_range,relayvol_range,recordinput,target_freq,powerwifi_range,hostname,username,password,portnum,database,table,new_sn))
UnboundLocalError: local variable 'new_sn' referenced before assignment
Traceback (most recent call last):
  File "/root/Desktop/PCBA2/bin/pcba_ate.py", line 327, in auto_clicked
    _thread.start_new_thread(auto,(ser_linux,resq,res_value,dc1_range,tp28_range,ser_ir,ser_switch,sensevol_range,relayvol_range,recordinput,target_freq,powerwifi_range,hostname,username,password,portnum,database,table,new_sn))
UnboundLocalError: local variable 'new_sn' referenced before assignment
Traceback (most recent call last):
  File "/root/Desktop/PCBA2/bin/pcba_ate.py", line 327, in auto_clicked
    _thread.start_new_thread(auto,(ser_linux,resq,res_value,dc1_range,tp28_range,ser_ir,ser_switch,sensevol_range,relayvol_range,recordinput,target_freq,powerwifi_range,hostname,username,password,portnum,database,table,new_sn))
UnboundLocalError: local variable 'new_sn' referenced before assignment
Traceback (most recent call last):
  File "/root/Desktop/PCBA2/bin/pcba_ate.py", line 346, in submit_clicked
    index_value=res_value["SNID"][1]
KeyError: 'SNID'
Traceback (most recent call last):
  File "/root/Desktop/PCBA/bin/pcba_func.py", line 1307, in auto
    info_rw(ser,hostname,username,password,portnum,database,record_server_tb,new_sn,resq)
NameError: name 'record_server_tb' is not defined
Traceback (most recent call last):
  File "/root/Desktop/PCBA/bin/pcba_func.py", line 1297, in auto
    fetch_power(ser,resq,target_freq,powerwifi_range)
  File "/root/Desktop/PCBA/bin/pcba_func.py", line 497, in fetch_power
    hackrf.sample_rate = 20e6
NameError: name 'hackrf' is not defined
Traceback (most recent call last):
  File "pcba_ate.py", line 331, in auto_clicked
    _thread.start_new_thread(auto,(ser_linux,resq,res_value,dc1_range,tp28_range,ser_ir,ser_switch,sensevol_range,relayvol_range,recordinput,target_freq,powerwifi_range,hostname,username,password,portnum,database,record_server_tb,table,new_sn))
UnboundLocalError: local variable 'new_sn' referenced before assignment
Traceback (most recent call last):
  File "pcba_ate.py", line 331, in auto_clicked
    _thread.start_new_thread(auto,(ser_linux,resq,res_value,dc1_range,tp28_range,ser_ir,ser_switch,sensevol_range,relayvol_range,recordinput,target_freq,powerwifi_range,hostname,username,password,portnum,database,record_server_tb,table,new_sn))
UnboundLocalError: local variable 'new_sn' referenced before assignment
Traceback (most recent call last):
  File "pcba_ate.py", line 331, in auto_clicked
    _thread.start_new_thread(auto,(ser_linux,resq,res_value,dc1_range,tp28_range,ser_ir,ser_switch,sensevol_range,relayvol_range,recordinput,target_freq,powerwifi_range,hostname,username,password,portnum,database,record_server_tb,table,new_sn))
UnboundLocalError: local variable 'new_sn' referenced before assignment
Traceback (most recent call last):
  File "pcba_ate.py", line 331, in auto_clicked
    _thread.start_new_thread(auto,(ser_linux,resq,res_value,dc1_range,tp28_range,ser_ir,ser_switch,sensevol_range,relayvol_range,recordinput,target_freq,powerwifi_range,hostname,username,password,portnum,database,record_server_tb,table,new_sn))
UnboundLocalError: local variable 'new_sn' referenced before assignment
Traceback (most recent call last):
  File "pcba_ate.py", line 331, in auto_clicked
    _thread.start_new_thread(auto,(ser_linux,resq,res_value,dc1_range,tp28_range,ser_ir,ser_switch,sensevol_range,relayvol_range,recordinput,target_freq,powerwifi_range,hostname,username,password,portnum,database,record_server_tb,table,new_sn))
UnboundLocalError: local variable 'new_sn' referenced before assignment
Traceback (most recent call last):
  File "pcba_ate.py", line 331, in auto_clicked
    _thread.start_new_thread(auto,(ser_linux,resq,res_value,dc1_range,tp28_range,ser_ir,ser_switch,sensevol_range,relayvol_range,recordinput,target_freq,powerwifi_range,hostname,username,password,portnum,database,record_server_tb,table,new_sn))
UnboundLocalError: local variable 'new_sn' referenced before assignment
Traceback (most recent call last):
  File "pcba_ate.py", line 331, in auto_clicked
    _thread.start_new_thread(auto,(ser_linux,resq,res_value,dc1_range,tp28_range,ser_ir,ser_switch,sensevol_range,relayvol_range,recordinput,target_freq,powerwifi_range,hostname,username,password,portnum,database,record_server_tb,table,new_sn))
UnboundLocalError: local variable 'new_sn' referenced before assignment
Traceback (most recent call last):
  File "pcba_ate.py", line 331, in auto_clicked
    _thread.start_new_thread(auto,(ser_linux,resq,res_value,dc1_range,tp28_range,ser_ir,ser_switch,sensevol_range,relayvol_range,recordinput,target_freq,powerwifi_range,hostname,username,password,portnum,database,record_server_tb,table,new_sn))
UnboundLocalError: local variable 'new_sn' referenced before assignment
Traceback (most recent call last):
  File "pcba_ate.py", line 331, in auto_clicked
    _thread.start_new_thread(auto,(ser_linux,resq,res_value,dc1_range,tp28_range,ser_ir,ser_switch,sensevol_range,relayvol_range,recordinput,target_freq,powerwifi_range,hostname,username,password,portnum,database,record_server_tb,table,new_sn))
UnboundLocalError: local variable 'new_sn' referenced before assignment
Traceback (most recent call last):
  File "pcba_ate.py", line 331, in auto_clicked
    _thread.start_new_thread(auto,(ser_linux,resq,res_value,dc1_range,tp28_range,ser_ir,ser_switch,sensevol_range,relayvol_range,recordinput,target_freq,powerwifi_range,hostname,username,password,portnum,database,record_server_tb,table,new_sn))
UnboundLocalError: local variable 'new_sn' referenced before assignment
Traceback (most recent call last):
  File "pcba_ate.py", line 331, in auto_clicked
    _thread.start_new_thread(auto,(ser_linux,resq,res_value,dc1_range,tp28_range,ser_ir,ser_switch,sensevol_range,relayvol_range,recordinput,target_freq,powerwifi_range,hostname,username,password,portnum,database,record_server_tb,table,new_sn))
UnboundLocalError: local variable 'new_sn' referenced before assignment
Traceback (most recent call last):
  File "/root/Desktop/PCBA/bin/pcba_ate.py", line 331, in auto_clicked
    _thread.start_new_thread(auto,(ser_linux,resq,res_value,dc1_range,tp28_range,ser_ir,ser_switch,sensevol_range,relayvol_range,recordinput,target_freq,powerwifi_range,hostname,username,password,portnum,database,record_server_tb,table,new_sn))
UnboundLocalError: local variable 'new_sn' referenced before assignment
Traceback (most recent call last):
  File "/root/Desktop/PCBA/bin/pcba_ate.py", line 774, in operate
    if getresq[4]<=100:
TypeError: '<=' not supported between instances of 'str' and 'int'
Traceback (most recent call last):
  File "/root/Desktop/PCBA/bin/pcba_func.py", line 605, in info_rw
    mac_num=server_mac[0][0]
IndexError: list index out of range

During handling of the above exception, another exception occurred:

Traceback (most recent call last):
  File "/usr/local/lib/python3.7/dist-packages/pymysql/connections.py", line 571, in connect
    **kwargs)
  File "/usr/lib/python3.7/socket.py", line 727, in create_connection
    raise err
  File "/usr/lib/python3.7/socket.py", line 716, in create_connection
    sock.connect(sa)
OSError: [Errno 101] Network is unreachable

During handling of the above exception, another exception occurred:

Traceback (most recent call last):
  File "/root/Desktop/PCBA/bin/pcba_func.py", line 685, in elan_get_mac_addr
    db=pymysql.connect(hostname,username,password,database,port=int(portnum))
  File "/usr/local/lib/python3.7/dist-packages/pymysql/__init__.py", line 94, in Connect
    return Connection(*args, **kwargs)
  File "/usr/local/lib/python3.7/dist-packages/pymysql/connections.py", line 327, in __init__
    self.connect()
  File "/usr/local/lib/python3.7/dist-packages/pymysql/connections.py", line 619, in connect
    raise exc
pymysql.err.OperationalError: (2003, "Can't connect to MySQL server on '172.20.3.177' ([Errno 101] Network is unreachable)")

During handling of the above exception, another exception occurred:

Traceback (most recent call last):
  File "/root/Desktop/PCBA/bin/pcba_func.py", line 1318, in auto
    info_rw(ser,hostname,username,password,portnum,database,record_server_tb,table,new_sn,resq)
  File "/root/Desktop/PCBA/bin/pcba_func.py", line 611, in info_rw
    mac_num=elan_get_mac_addr(hostname,username,password,portnum,database,table)
  File "/root/Desktop/PCBA/bin/pcba_func.py", line 728, in elan_get_mac_addr
    db.rollback()
UnboundLocalError: local variable 'db' referenced before assignment
Traceback (most recent call last):
  File "pcba_ate.py", line 334, in auto_clicked
    _thread.start_new_thread(auto,(ser_linux,resq,res_value,dc1_range,tp28_range,ser_ir,ser_switch,sensevol_range,relayvol_range,recordinput,target_freq,powerwifi_range,hostname,username,password,portnum,database,record_server_tb,table,new_sn))
UnboundLocalError: local variable 'new_sn' referenced before assignment
Traceback (most recent call last):
  File "pcba_ate.py", line 775, in operate
    restmac=int(getresq[5])
IndexError: list index out of range
Traceback (most recent call last):
  File "pcba_ate.py", line 775, in operate
    restmac=int(getresq[5])
IndexError: list index out of range
Traceback (most recent call last):
  File "pcba_ate.py", line 334, in auto_clicked
    _thread.start_new_thread(auto,(ser_linux,resq,res_value,dc1_range,tp28_range,ser_ir,ser_switch,sensevol_range,relayvol_range,recordinput,target_freq,powerwifi_range,hostname,username,password,portnum,database,record_server_tb,table,new_sn))
UnboundLocalError: local variable 'new_sn' referenced before assignment
Traceback (most recent call last):
  File "pcba_ate.py", line 334, in auto_clicked
    _thread.start_new_thread(auto,(ser_linux,resq,res_value,dc1_range,tp28_range,ser_ir,ser_switch,sensevol_range,relayvol_range,recordinput,target_freq,powerwifi_range,hostname,username,password,portnum,database,record_server_tb,table,new_sn))
UnboundLocalError: local variable 'new_sn' referenced before assignment
Traceback (most recent call last):
  File "pcba_ate.py", line 334, in auto_clicked
    _thread.start_new_thread(auto,(ser_linux,resq,res_value,dc1_range,tp28_range,ser_ir,ser_switch,sensevol_range,relayvol_range,recordinput,target_freq,powerwifi_range,hostname,username,password,portnum,database,record_server_tb,table,new_sn))
UnboundLocalError: local variable 'new_sn' referenced before assignment
Traceback (most recent call last):
  File "pcba_ate.py", line 334, in auto_clicked
    _thread.start_new_thread(auto,(ser_linux,resq,res_value,dc1_range,tp28_range,ser_ir,ser_switch,sensevol_range,relayvol_range,recordinput,target_freq,powerwifi_range,hostname,username,password,portnum,database,record_server_tb,table,new_sn))
UnboundLocalError: local variable 'new_sn' referenced before assignment
Traceback (most recent call last):
  File "pcba_ate.py", line 334, in auto_clicked
    _thread.start_new_thread(auto,(ser_linux,resq,res_value,dc1_range,tp28_range,ser_ir,ser_switch,sensevol_range,relayvol_range,recordinput,target_freq,powerwifi_range,hostname,username,password,portnum,database,record_server_tb,table,new_sn))
UnboundLocalError: local variable 'new_sn' referenced before assignment
Traceback (most recent call last):
  File "/root/Desktop/PCBA/bin/pcba_func.py", line 1331, in auto
    info_rw(ser,hostname,username,password,portnum,database,record_server_db,record_server_tb,table,new_sn,resq)
NameError: name 'record_server_db' is not defined
Traceback (most recent call last):
  File "pcba_ate.py", line 334, in auto_clicked
    _thread.start_new_thread(auto,(ser_linux,resq,res_value,dc1_range,tp28_range,ser_ir,ser_switch,sensevol_range,relayvol_range,recordinput,target_freq,powerwifi_range,hostname,username,password,portnum,database,record_server_db,record_server_tb,table,new_sn))
UnboundLocalError: local variable 'new_sn' referenced before assignment
Traceback (most recent call last):
  File "pcba_ate.py", line 334, in auto_clicked
    _thread.start_new_thread(auto,(ser_linux,resq,res_value,dc1_range,tp28_range,ser_ir,ser_switch,sensevol_range,relayvol_range,recordinput,target_freq,powerwifi_range,hostname,username,password,portnum,database,record_server_db,record_server_tb,table,new_sn))
UnboundLocalError: local variable 'new_sn' referenced before assignment
Traceback (most recent call last):
  File "/root/Desktop/PCBA/bin/pcba_func.py", line 1277, in auto
    fetch_power(ser,resq,target_freq,powerwifi_range)
  File "/root/Desktop/PCBA/bin/pcba_func.py", line 475, in fetch_power
    hackrf.sample_rate = 20e6
  File "/root/Desktop/PCBA/bin/rasp_libhackrf.py", line 440, in set_sample_rate
    raise IOError('Sample rate set failure')
OSError: Sample rate set failure
Traceback (most recent call last):
  File "/root/Desktop/PCBA/bin/pcba_func.py", line 1277, in auto
    fetch_power(ser,resq,target_freq,powerwifi_range)
  File "/root/Desktop/PCBA/bin/pcba_func.py", line 475, in fetch_power
    hackrf.sample_rate = 20e6
  File "/root/Desktop/PCBA/bin/rasp_libhackrf.py", line 440, in set_sample_rate
    raise IOError('Sample rate set failure')
OSError: Sample rate set failure
Traceback (most recent call last):
  File "/root/Desktop/PCBA/bin/pcba_func.py", line 1277, in auto
    fetch_power(ser,resq,target_freq,powerwifi_range)
  File "/root/Desktop/PCBA/bin/pcba_func.py", line 475, in fetch_power
    hackrf.sample_rate = 20e6
NameError: name 'hackrf' is not defined
Traceback (most recent call last):
  File "/root/Desktop/PCBA/bin/pcba_func.py", line 1277, in auto
    fetch_power(ser,resq,target_freq,powerwifi_range)
  File "/root/Desktop/PCBA/bin/pcba_func.py", line 475, in fetch_power
    hackrf.sample_rate = 20e6
NameError: name 'hackrf' is not defined
Traceback (most recent call last):
  File "/root/Desktop/PCBA/bin/pcba_func.py", line 1277, in auto
    fetch_power(ser,resq,target_freq,powerwifi_range)
  File "/root/Desktop/PCBA/bin/pcba_func.py", line 475, in fetch_power
    hackrf.sample_rate = 20e6
NameError: name 'hackrf' is not defined
Traceback (most recent call last):
  File "/root/Desktop/PCBA/bin/pcba_func.py", line 1277, in auto
    fetch_power(ser,resq,target_freq,powerwifi_range)
  File "/root/Desktop/PCBA/bin/pcba_func.py", line 475, in fetch_power
    hackrf.sample_rate = 20e6
NameError: name 'hackrf' is not defined
Traceback (most recent call last):
  File "/root/Desktop/PCBA/bin/pcba_func.py", line 1277, in auto
    fetch_power(ser,resq,target_freq,powerwifi_range)
  File "/root/Desktop/PCBA/bin/pcba_func.py", line 475, in fetch_power
    hackrf.sample_rate = 20e6
NameError: name 'hackrf' is not defined
Traceback (most recent call last):
  File "/root/Desktop/PCBA/bin/pcba_func.py", line 1277, in auto
    fetch_power(ser,resq,target_freq,powerwifi_range)
  File "/root/Desktop/PCBA/bin/pcba_func.py", line 475, in fetch_power
    hackrf.sample_rate = 20e6
NameError: name 'hackrf' is not defined
Traceback (most recent call last):
  File "pcba_ate.py", line 334, in auto_clicked
    _thread.start_new_thread(auto,(ser_linux,resq,res_value,dc1_range,tp28_range,ser_ir,ser_switch,sensevol_range,relayvol_range,recordinput,target_freq,powerwifi_range,hostname,username,password,portnum,database,record_server_db,record_server_tb,table,new_sn))
UnboundLocalError: local variable 'new_sn' referenced before assignment
Traceback (most recent call last):
  File "pcba_ate.py", line 334, in auto_clicked
    _thread.start_new_thread(auto,(ser_linux,resq,res_value,dc1_range,tp28_range,ser_ir,ser_switch,sensevol_range,relayvol_range,recordinput,target_freq,powerwifi_range,hostname,username,password,portnum,database,record_server_db,record_server_tb,table,new_sn))
UnboundLocalError: local variable 'new_sn' referenced before assignment
Traceback (most recent call last):
  File "pcba_ate.py", line 334, in auto_clicked
    _thread.start_new_thread(auto,(ser_linux,resq,res_value,dc1_range,tp28_range,ser_ir,ser_switch,sensevol_range,relayvol_range,recordinput,target_freq,powerwifi_range,hostname,username,password,portnum,database,record_server_db,record_server_tb,table,new_sn))
UnboundLocalError: local variable 'new_sn' referenced before assignment
Traceback (most recent call last):
  File "pcba_ate.py", line 334, in auto_clicked
    _thread.start_new_thread(auto,(ser_linux,resq,res_value,dc1_range,tp28_range,ser_ir,ser_switch,sensevol_range,relayvol_range,recordinput,target_freq,powerwifi_range,hostname,username,password,portnum,database,record_server_db,record_server_tb,table,new_sn))
UnboundLocalError: local variable 'new_sn' referenced before assignment
Traceback (most recent call last):
  File "pcba_ate.py", line 334, in auto_clicked
    _thread.start_new_thread(auto,(ser_linux,resq,res_value,dc1_range,tp28_range,ser_ir,ser_switch,sensevol_range,relayvol_range,recordinput,target_freq,powerwifi_range,hostname,username,password,portnum,database,record_server_db,record_server_tb,table,new_sn))
UnboundLocalError: local variable 'new_sn' referenced before assignment
Traceback (most recent call last):
  File "pcba_ate.py", line 334, in auto_clicked
    _thread.start_new_thread(auto,(ser_linux,resq,res_value,dc1_range,tp28_range,ser_ir,ser_switch,sensevol_range,relayvol_range,recordinput,target_freq,powerwifi_range,hostname,username,password,portnum,database,record_server_db,record_server_tb,table,new_sn))
UnboundLocalError: local variable 'new_sn' referenced before assignment
Traceback (most recent call last):
  File "/root/Desktop/PCBA/bin/pcba_func.py", line 184, in uart_login
    data=ser.read_all()
  File "/usr/lib/python3/dist-packages/serial/serialutil.py", line 648, in read_all
    return self.read(self.in_waiting)
  File "/usr/lib/python3/dist-packages/serial/serialposix.py", line 467, in in_waiting
    s = fcntl.ioctl(self.fd, TIOCINQ, TIOCM_zero_str)
OSError: [Errno 5] Input/output error

During handling of the above exception, another exception occurred:

Traceback (most recent call last):
  File "/usr/lib/python3/dist-packages/serial/serialposix.py", line 537, in write
    n = os.write(self.fd, d)
OSError: [Errno 5] Input/output error

During handling of the above exception, another exception occurred:

Traceback (most recent call last):
  File "/root/Desktop/PCBA/bin/pcba_func.py", line 1265, in auto
    uart_login(ser,ser_switch,resq)
  File "/root/Desktop/PCBA/bin/pcba_func.py", line 224, in uart_login
    ser.write(chr(0x03).encode())
  File "/usr/lib/python3/dist-packages/serial/serialposix.py", line 571, in write
    raise SerialException('write failed: {}'.format(e))
serial.serialutil.SerialException: write failed: [Errno 5] Input/output error
Traceback (most recent call last):
  File "/root/Desktop/PCBA/bin/pcba_func.py", line 128, in uart_login
    ser.flushInput()
  File "/usr/lib/python3/dist-packages/serial/serialutil.py", line 584, in flushInput
    self.reset_input_buffer()
  File "/usr/lib/python3/dist-packages/serial/serialposix.py", line 595, in reset_input_buffer
    termios.tcflush(self.fd, termios.TCIFLUSH)
termios.error: (5, 'Input/output error')

During handling of the above exception, another exception occurred:

Traceback (most recent call last):
  File "/usr/lib/python3/dist-packages/serial/serialposix.py", line 537, in write
    n = os.write(self.fd, d)
OSError: [Errno 5] Input/output error

During handling of the above exception, another exception occurred:

Traceback (most recent call last):
  File "/root/Desktop/PCBA/bin/pcba_func.py", line 1265, in auto
    uart_login(ser,ser_switch,resq)
  File "/root/Desktop/PCBA/bin/pcba_func.py", line 224, in uart_login
    ser.write(chr(0x03).encode())
  File "/usr/lib/python3/dist-packages/serial/serialposix.py", line 571, in write
    raise SerialException('write failed: {}'.format(e))
serial.serialutil.SerialException: write failed: [Errno 5] Input/output error
Traceback (most recent call last):
  File "/root/Desktop/PCBA/bin/pcba_func.py", line 184, in uart_login
    data=ser.read_all()
  File "/usr/lib/python3/dist-packages/serial/serialutil.py", line 648, in read_all
    return self.read(self.in_waiting)
  File "/usr/lib/python3/dist-packages/serial/serialposix.py", line 467, in in_waiting
    s = fcntl.ioctl(self.fd, TIOCINQ, TIOCM_zero_str)
OSError: [Errno 5] Input/output error

During handling of the above exception, another exception occurred:

Traceback (most recent call last):
  File "/usr/lib/python3/dist-packages/serial/serialposix.py", line 537, in write
    n = os.write(self.fd, d)
OSError: [Errno 5] Input/output error

During handling of the above exception, another exception occurred:

Traceback (most recent call last):
  File "/root/Desktop/PCBA/bin/pcba_func.py", line 1265, in auto
    uart_login(ser,ser_switch,resq)
  File "/root/Desktop/PCBA/bin/pcba_func.py", line 224, in uart_login
    ser.write(chr(0x03).encode())
  File "/usr/lib/python3/dist-packages/serial/serialposix.py", line 571, in write
    raise SerialException('write failed: {}'.format(e))
serial.serialutil.SerialException: write failed: [Errno 5] Input/output error
Traceback (most recent call last):
  File "/root/Desktop/PCBA/bin/pcba_func.py", line 128, in uart_login
    ser.flushInput()
  File "/usr/lib/python3/dist-packages/serial/serialutil.py", line 584, in flushInput
    self.reset_input_buffer()
  File "/usr/lib/python3/dist-packages/serial/serialposix.py", line 595, in reset_input_buffer
    termios.tcflush(self.fd, termios.TCIFLUSH)
termios.error: (5, 'Input/output error')

During handling of the above exception, another exception occurred:

Traceback (most recent call last):
  File "/usr/lib/python3/dist-packages/serial/serialposix.py", line 537, in write
    n = os.write(self.fd, d)
OSError: [Errno 5] Input/output error

During handling of the above exception, another exception occurred:

Traceback (most recent call last):
  File "/root/Desktop/PCBA/bin/pcba_func.py", line 1265, in auto
    uart_login(ser,ser_switch,resq)
  File "/root/Desktop/PCBA/bin/pcba_func.py", line 224, in uart_login
    ser.write(chr(0x03).encode())
  File "/usr/lib/python3/dist-packages/serial/serialposix.py", line 571, in write
    raise SerialException('write failed: {}'.format(e))
serial.serialutil.SerialException: write failed: [Errno 5] Input/output error
